<robot xmlns:xacro="http://www.ros.org/wiki/xacro">

    <xacro:include filename="$(find rm_description)/urdf/common/friction.urdf.xacro"/>
    <!--    <xacro:include filename="$(find rm_description)/urdf/standard/gimbal.urdf.xacro"/>-->


    <xacro:property name="wheel_offset_x" value="0.024952"/>
    <xacro:property name="wheel_offset_y" value="0.03650"/>
    <xacro:property name="wheel_offset_z" value="0.0222"/>

    <xacro:friction_wheel prefixs="left" connected_to="pitch"
                          wheel_x_offset="${wheel_offset_x}" wheel_y_offset="${wheel_offset_y}"
                          wheel_z_offset="${wheel_offset_z}"/>

    <xacro:friction_wheel prefixs="right" connected_to="pitch"
                          wheel_x_offset="${wheel_offset_x}" wheel_y_offset="${-wheel_offset_y}"
                          wheel_z_offset="${wheel_offset_z}"/>


    <link name="trigger">
        <inertial>
            <mass value="0.120176"/>
            <origin xyz="-0.060153 -0.000105 0.019583"/>
            <inertia ixx="4.8871942e-5" ixy="-1.79485e-7" ixz="-3.26633e-7" iyy="4.8114947e-5"
                     iyz="-3.27658e-7" izz="2.3966289e-5"/>
        </inertial>
        <visual>
            <origin xyz="0 0 0" rpy="0 0 0"/>
            <geometry>
                <mesh filename="package://rm_description/meshes/little_standard/trigger.stl" scale="0.001 0.001 0.001"/>
            </geometry>
        </visual>
        <collision>
            <origin xyz="0 0 0" rpy="0 0 0"/>
            <geometry>
                <mesh filename="package://rm_description/meshes/little_standard/trigger.stl" scale="0.001 0.001 0.001"/>
            </geometry>
        </collision>
    </link>

    <joint name="trigger_joint" type="continuous">
        <origin xyz="-0.060048 0 0.0212" rpy="0 0 0"/>
        <dynamics damping="0.0" friction="0.01"/>
        <limit effort="3.0" velocity="43.54" lower="-1e16" upper="1e16"/>
        <parent link="pitch"/>
        <child link="trigger"/>
        <axis xyz="0 0 1 "/>

    </joint>

    <link name="cover">
        <inertial>
            <mass value="0.116618"/>
            <origin xyz="-0.008815 -0.014974 -0.024892"/>
            <inertia ixx="1.903e-4" ixy="-6.3287853e-5" ixz="2.7568372e-5" iyy="1.383e-4" iyz="4.5212156e-5"
                     izz="2.4e-4"/>
        </inertial>
    </link>

    <joint name="cover_joint" type="revolute">
        <axis xyz="0 1 0"/>
        <origin xyz="-0.047515 0.0776 0.134638"/>
        <limit effort="3.0" velocity="43.54" lower="0" upper="1.57"/>
        <dynamics damping="0.0" friction="0.1"/>
        <parent link="pitch"/>
        <child link="cover"/>
    </joint>

</robot>
